Workbook

Sheet Sheet1
A1: Season | B1: Start_Date | C1: Result | D1: Margin | E1: BR | F1: Toss | G1: Bat | H1: Opposition | I1: Ground | J1: Home/Away
A2: =YEAR(Sheet1!$B2) -> 2008 | B2: 39557 | C2: won | D2: 33 runs | F2: won | G2: 1st | H2: v Kings XI | I2: Mohali | J2: =IF(Sheet1!$I2="Chennai","Home","Away") -> Away
A3: =YEAR(Sheet1!$B3) -> 2008 | B3: 39561 | C3: won | D3: 6 runs | F3: lost | G3: 1st | H3: v MI | I3: Chennai | J3: =IF(Sheet1!$I3="Chennai","Home","Away") -> Home
A4: =YEAR(Sheet1!$B4) -> 2008 | B4: 39564 | C4: won | D4: 9 wickets | E4: 18 | F4: lost | G4: 2nd | H4: v KKR | I4: Chennai | J4: =IF(Sheet1!$I4="Chennai","Home","Away") -> Home
A5: =YEAR(Sheet1!$B5) -> 2008 | B5: 39566 | C5: won | D5: 13 runs | F5: won | G5: 1st | H5: v RCB | I5: Bengaluru | J5: =IF(Sheet1!$I5="Chennai","Home","Away") -> Away
A6: =YEAR(Sheet1!$B6) -> 2008 | B6: 39570 | C6: lost | D6: 8 wickets | E6: 6 | F6: won | G6: 1st | H6: v Daredevils | I6: Chennai | J6: =IF(Sheet1!$I6="Chennai","Home","Away") -> Home
A7: =YEAR(Sheet1!$B7) -> 2008 | B7: 39572 | C7: lost | D7: 8 wickets | E7: 34 | F7: won | G7: 1st | H7: v RR | I7: Jaipur | J7: =IF(Sheet1!$I7="Chennai","Home","Away") -> Away
A8: =YEAR(Sheet1!$B8) -> 2008 | B8: 39574 | C8: lost | D8: 7 wickets | E8: 12 | F8: lost | G8: 1st | H8: v Chargers | I8: Chennai | J8: =IF(Sheet1!$I8="Chennai","Home","Away") -> Home
A9: =YEAR(Sheet1!$B9) -> 2008 | B9: 39576 | C9: won | D9: 4 wickets | E9: 0 | F9: won | G9: 2nd | H9: v Daredevils | I9: Delhi | J9: =IF(Sheet1!$I9="Chennai","Home","Away") -> Away
A10: =YEAR(Sheet1!$B10) -> 2008 | B10: 39578 | C10: won | D10: 18 runs | F10: lost | G10: 1st | H10: v Kings XI | I10: Chennai | J10: =IF(Sheet1!$I10="Chennai","Home","Away") -> Home
A11: =YEAR(Sheet1!$B11) -> 2008 | B11: 39582 | C11: lost | D11: 9 wickets | E11: 37 | F11: lost | G11: 1st | H11: v MI | I11: Wankhede | J11: =IF(Sheet1!$I11="Chennai","Home","Away") -> Away
A12: =YEAR(Sheet1!$B12) -> 2008 | B12: 39586 | C12: won | D12: 3 runs | F12: lost | G12: 2nd | H12: v KKR | I12: Eden Gardens | J12: =IF(Sheet1!$I12="Chennai","Home","Away") -> Away
A13: =YEAR(Sheet1!$B13) -> 2008 | B13: 39589 | C13: lost | D13: 14 runs | F13: lost | G13: 2nd | H13: v RCB | I13: Chennai | J13: =IF(Sheet1!$I13="Chennai","Home","Away") -> Home
A14: =YEAR(Sheet1!$B14) -> 2008 | B14: 39592 | C14: lost | D14: 10 runs | F14: lost | G14: 2nd | H14: v RR | I14: Chennai | J14: =IF(Sheet1!$I14="Chennai","Home","Away") -> Home
A15: =YEAR(Sheet1!$B15) -> 2008 | B15: 39595 | C15: won | D15: 7 wickets | E15: 4 | F15: lost | G15: 2nd | H15: v Chargers | I15: Hyderabad | J15: =IF(Sheet1!$I15="Chennai","Home","Away") -> Away
A16: =YEAR(Sheet1!$B16) -> 2008 | B16: 39599 | C16: won | D16: 9 wickets | E16: 31 | F16: lost | G16: 2nd | H16: v Kings XI | I16: Wankhede | J16: =IF(Sheet1!$I16="Chennai","Home","Away") -> Away
A17: =YEAR(Sheet1!$B17) -> 2008 | B17: 39600 | C17: lost | D17: 3 wickets | E17: 0 | F17: lost | G17: 1st | H17: v RR | I17: DY Patil | J17: =IF(Sheet1!$I17="Chennai","Home","Away") -> Away
A18: =YEAR(Sheet1!$B18) -> 2009 | B18: 39921 | C18: lost | D18: 19 runs | F18: won | G18: 2nd | H18: v MI | I18: Cape Town | J18: =IF(Sheet1!$I18="Chennai","Home","Away") -> Away
A19: =YEAR(Sheet1!$B19) -> 2009 | B19: 39923 | C19: won | D19: 92 runs | F19: won | G19: 1st | H19: v RCB | I19: Gqeberha | J19: =IF(Sheet1!$I19="Chennai","Home","Away") -> Away
A20: =YEAR(Sheet1!$B20) -> 2009 | B20: 39926 | C20: lost | D20: 9 runs | F20: lost | G20: 2nd | H20: v Daredevils | I20: Durban | J20: =IF(Sheet1!$I20="Chennai","Home","Away") -> Away
A21: =YEAR(Sheet1!$B21) -> 2009 | B21: 39930 | C21: lost | D21: 6 wickets | E21: 3 | F21: lost | G21: 1st | H21: v Chargers | I21: Durban | J21: =IF(Sheet1!$I21="Chennai","Home","Away") -> Away
A22: =YEAR(Sheet1!$B22) -> 2009 | B22: 39933 | C22: won | D22: 38 runs | F22: lost | G22: 1st | H22: v RR | I22: Centurion | J22: =IF(Sheet1!$I22="Chennai","Home","Away") -> Away
A23: =YEAR(Sheet1!$B23) -> 2009 | B23: 39935 | C23: won | D23: 18 runs | F23: lost | G23: 1st | H23: v Daredevils | I23: Johannesburg | J23: =IF(Sheet1!$I23="Chennai","Home","Away") -> Away
A24: =YEAR(Sheet1!$B24) -> 2009 | B24: 39937 | C24: won | D24: 78 runs | F24: won | G24: 1st | H24: v Chargers | I24: East London | J24: =IF(Sheet1!$I24="Chennai","Home","Away") -> Away
A25: =YEAR(Sheet1!$B25) -> 2009 | B25: 39940 | C25: won | D25: 12 runs | F25: won | G25: 1st | H25: v Kings XI | I25: Centurion | J25: =IF(Sheet1!$I25="Chennai","Home","Away") -> Away
A26: =YEAR(Sheet1!$B26) -> 2009 | B26: 39942 | C26: won | D26: 7 wickets | E26: 10 | F26: lost | G26: 2nd | H26: v RR | I26: Kimberley | J26: =IF(Sheet1!$I26="Chennai","Home","Away") -> Away
A27: =YEAR(Sheet1!$B27) -> 2009 | B27: 39947 | C27: lost | D27: 2 wickets | E27: 2 | F27: won | G27: 1st | H27: v RCB | I27: Durban | J27: =IF(Sheet1!$I27="Chennai","Home","Away") -> Away
A28: =YEAR(Sheet1!$B28) -> 2009 | B28: 39949 | C28: won | D28: 7 wickets | E28: 5 | F28: lost | G28: 2nd | H28: v MI | I28: Gqeberha | J28: =IF(Sheet1!$I28="Chennai","Home","Away") -> Away
A29: =YEAR(Sheet1!$B29) -> 2009 | B29: 39951 | C29: lost | D29: 7 wickets | E29: 0 | F29: won | G29: 1st | H29: v KKR | I29: Centurion | J29: =IF(Sheet1!$I29="Chennai","Home","Away") -> Away
A30: =YEAR(Sheet1!$B30) -> 2009 | B30: 39953 | C30: won | D30: 24 runs | F30: won | G30: 1st | H30: v Kings XI | I30: Durban | J30: =IF(Sheet1!$I30="Chennai","Home","Away") -> Away
A31: =YEAR(Sheet1!$B31) -> 2009 | B31: 39956 | C31: lost | D31: 6 wickets | E31: 7 | F31: lost | G31: 1st | H31: v RCB | I31: Johannesburg | J31: =IF(Sheet1!$I31="Chennai","Home","Away") -> Away
A32: =YEAR(Sheet1!$B32) -> 2010 | B32: 40251 | C32: lost | D32: 31 runs | F32: lost | G32: 2nd | H32: v Chargers | I32: Chennai | J32: =IF(Sheet1!$I32="Chennai","Home","Away") -> Home
A33: =YEAR(Sheet1!$B33) -> 2010 | B33: 40253 | C33: won | D33: 55 runs | F33: won | G33: 1st | H33: v KKR | I33: Eden Gardens | J33: =IF(Sheet1!$I33="Chennai","Home","Away") -> Away
A34: =YEAR(Sheet1!$B34) -> 2010 | B34: 40256 | C34: won | D34: 5 wickets | E34: 5 | F34: lost | G34: 2nd | H34: v Daredevils | I34: Delhi | J34: =IF(Sheet1!$I34="Chennai","Home","Away") -> Away
A35: =YEAR(Sheet1!$B35) -> 2010 | B35: 40258 | C35: tied | D35: - | F35: won | G35: 2nd | H35: v Kings XI | I35: Chennai | J35: =IF(Sheet1!$I35="Chennai","Home","Away") -> Home
A36: =YEAR(Sheet1!$B36) -> 2010 | B36: 40260 | C36: lost | D36: 36 runs | F36: won | G36: 2nd | H36: v RCB | I36: Bengaluru | J36: =IF(Sheet1!$I36="Chennai","Home","Away") -> Away
A37: =YEAR(Sheet1!$B37) -> 2010 | B37: 40262 | C37: lost | D37: 5 wickets | E37: 6 | F37: lost | G37: 1st | H37: v MI | I37: Brabourne | J37: =IF(Sheet1!$I37="Chennai","Home","Away") -> Away
A38: =YEAR(Sheet1!$B38) -> 2010 | B38: 40265 | C38: lost | D38: 17 runs | F38: lost | G38: 2nd | H38: v RR | I38: Ahmedabad | J38: =IF(Sheet1!$I38="Chennai","Home","Away") -> Away
A39: =YEAR(Sheet1!$B39) -> 2010 | B39: 40268 | C39: won | D39: 5 wickets | E39: 6 | F39: lost | G39: 2nd | H39: v RCB | I39: Chennai | J39: =IF(Sheet1!$I39="Chennai","Home","Away") -> Home
A40: =YEAR(Sheet1!$B40) -> 2010 | B40: 40271 | C40: won | D40: 23 runs | F40: won | G40: 1st | H40: v RR | I40: Chennai | J40: =IF(Sheet1!$I40="Chennai","Home","Away") -> Home
...
